Traceback (most recent call last):
  File "C:\Users\33678\.julia\conda\3\lib\site-packages\jupyter_cache\executors\utils.py", line 51, in single_nb_execution
    executenb(
  File "C:\Users\33678\.julia\conda\3\lib\site-packages\nbclient\client.py", line 1204, in execute
    return NotebookClient(nb=nb, resources=resources, km=km, **kwargs).execute()
  File "C:\Users\33678\.julia\conda\3\lib\site-packages\nbclient\util.py", line 84, in wrapped
    return just_run(coro(*args, **kwargs))
  File "C:\Users\33678\.julia\conda\3\lib\site-packages\nbclient\util.py", line 62, in just_run
    return loop.run_until_complete(coro)
  File "C:\Users\33678\.julia\conda\3\lib\asyncio\base_events.py", line 616, in run_until_complete
    return future.result()
  File "C:\Users\33678\.julia\conda\3\lib\site-packages\nbclient\client.py", line 663, in async_execute
    await self.async_execute_cell(
  File "C:\Users\33678\.julia\conda\3\lib\site-packages\nbclient\client.py", line 965, in async_execute_cell
    await self._check_raise_for_error(cell, cell_index, exec_reply)
  File "C:\Users\33678\.julia\conda\3\lib\site-packages\nbclient\client.py", line 862, in _check_raise_for_error
    raise CellExecutionError.from_cell_and_msg(cell, exec_reply_content)
nbclient.exceptions.CellExecutionError: An error occurred while executing the following cell:
------------------
pulse=1
Figure_Dir = "./figure/NC_PulseExp/"
# Figure_Dir = "./NC_PulseExp/"
# Figure_Dir = ""
cearth=15.0
baseline = "rcp60co2eqv3.csv"
year = 1801

filename = Figure_Dir+"Baseline="+baseline+",cearth=" + \
    str(cearth)+",year"+str(year)+",pulse="+str(pulse)+".png"
# Image("test.png")
filename
# Image(filename)
Image("./figure/NC_PulseExp/Baseline=rcp60co2eqv3.csv,cearth=0.3725,year1801,pulse=29.png")

------------------

[1;31m---------------------------------------------------------------------------[0m
[1;31mTypeError[0m                                 Traceback (most recent call last)
Input [1;32mIn [3][0m, in [0;36m<cell line: 14>[1;34m()[0m
[0;32m     12[0m filename
[0;32m     13[0m [38;5;66;03m# Image(filename)[39;00m
[1;32m---> 14[0m [43mImage[49m[43m([49m[38;5;124;43m"[39;49m[38;5;124;43m./figure/NC_PulseExp/Baseline=rcp60co2eqv3.csv,cearth=0.3725,year1801,pulse=29.png[39;49m[38;5;124;43m"[39;49m[43m)[49m

[1;31mTypeError[0m: 'module' object is not callable
TypeError: 'module' object is not callable

